<mujoco model="6dof_robot">
  <option timestep="0.002" gravity="0 0 -9.81"/>
  <statistic center="0 1 1" extent="2"/>


  <visual>
    <headlight diffuse="0.6 0.6 0.6" ambient="0.3 0.3 0.3" specular="0 0 0"/>
    <rgba haze="0.15 0.25 0.35 1"/>
    <global azimuth="120" elevation="-20"/>
  </visual>

  <asset>
    <!-- Подключаем файлы геометрии -->
    <mesh name="base_mesh" file="parts/base.stl"/>
    <mesh name="link1_mesh" file="parts/link1.stl"/>
    <mesh name="link2_mesh" file="parts/link2.stl"/>
    <mesh name="link3_mesh" file="parts/link3.stl"/>
    <mesh name="link4_mesh" file="parts/link4.stl"/>
    <mesh name="link5_mesh" file="parts/link5.stl"/>
    <mesh name="link6_mesh" file="parts/link6.stl"/>
    <mesh name="endEffector_mesh" file="parts/endEffector.stl"/>
    
    <!-- Текстура для пола -->
    <texture name="grid" type="2d" builtin="checker" width="512" height="512" rgb1="0.1 0.2 0.3" rgb2="0.2 0.3 0.4"/>
    <material name="floor_mat" texture="grid" texrepeat="1 1" texuniform="true" reflectance="0.2"/>
  </asset>

  <worldbody>
    
    <!-- Освещение -->
    <light pos="0 0 1.5" dir="0 0 -1" directional="true"/>

     <!-- Пол - плоскость размером 10x10 метров -->
    <geom name="floor" type="plane" size="1 1 0.05" pos="0 0 0" material="floor_mat" rgba="0.5 0.5 0.5 1"/>
    <!-- База (закреплена) -->
    <body name="base">
      <geom type="mesh" mesh="base_mesh" name="base_geom"/>
         <!-- Звено 1 -->
        <body name="link1" pos="0 0 0.016">
          <geom type="mesh" mesh="link1_mesh" name="link1_geom"/>
            <!-- Звено 2 -->
          <body name="link2" pos="0 0 0.232">
            <joint name='joint1' range='-360 360'/>
            <geom type="mesh" mesh="link2_mesh" name="link2_geom"/>
              <!-- Звено 3 -->
            <body name="link3" pos="0 0.1205 0">
              <joint name="joint2" axis='0 1 0' range='-360 360'/>
              <geom type="mesh" mesh="link3_mesh" name="link3_geom"/>
                <!-- Звено 4 -->
              <body name="link4" pos='0 -0.0975 0.375'>
                <joint name="joint3" type="hinge" range='-160 160' axis='0 1 0'/>
                <geom type="mesh" mesh="link4_mesh" name="link4_geom"/>
                  <!-- Звено 5 -->
                <body name="link5" pos="0 0.0975 0.295">
                  <joint name="joint4" axis='0 1 0' range='-360 360'/>
                  <geom type="mesh" mesh="link5_mesh" name="link5_geom"/>
                  <!-- Звено 6 -->
                  <body name="link6" pos='0 0 0.171'>
                    <joint name="joint5" range='-360 360'/>
                    <geom type="mesh" mesh="link6_mesh" name="link6_geom"/>
                      <!-- ендэффектор -->
                    <body name="end-effector" pos='0 0.1225 0'>
                      <joint name='joint6' axis='0 1 0' range='-360 360'/>
                      <geom type="mesh" mesh="endEffector_mesh" name="endeffector"/>
                    </body>

                  </body>
                </body>
              </body>
            </body>
          </body>
        </body>
    </body>
  </worldbody>
</mujoco>
